2025-09-07T16:12:15.000000000Z [inf]  Starting Container
2025-09-07T16:12:17.640643760Z [err]  INFO:     Started server process [1]
2025-09-07T16:12:17.640648229Z [err]  INFO:     Waiting for application startup.
2025-09-07T16:12:17.640652285Z [err]  INFO:     Application startup complete.
2025-09-07T16:12:17.640656751Z [err]  INFO:     Uvicorn running on http://0.0.0.0:8080 (Press CTRL+C to quit)
2025-09-07T16:12:57.644404139Z [inf]  Mengambil data baru untuk EURUSD=X dari yfinance...
2025-09-07T16:12:57.644409782Z [err]  /app/app.py:66: FutureWarning: YF.download() has changed argument auto_adjust default to True
2025-09-07T16:12:57.644418255Z [err]    data = yf.download(pair, period="5y", interval="1d", progress=False)
2025-09-07T16:12:57.644425033Z [inf]  INFO:     100.64.0.2:58966 - "GET /get-data?pair=EURUSD=X HTTP/1.1" 500 Internal Server Error
2025-09-07T16:12:57.644430958Z [err]  ERROR:    Exception in ASGI application
2025-09-07T16:12:57.644436665Z [err]  Traceback (most recent call last):
2025-09-07T16:12:57.644442343Z [err]    File "/opt/venv/lib/python3.12/site-packages/uvicorn/protocols/http/h11_impl.py", line 403, in run_asgi
2025-09-07T16:12:57.644447840Z [err]      result = await app(  # type: ignore[func-returns-value]
2025-09-07T16:12:57.644454132Z [err]               ^^^^^^^^^^^^^^^^^^^^^^^^^^^^^^^^^^^^^^^^^^^^^^
2025-09-07T16:12:57.644460468Z [err]    File "/opt/venv/lib/python3.12/site-packages/uvicorn/middleware/proxy_headers.py", line 60, in __call__
2025-09-07T16:12:57.644465968Z [err]      return await self.app(scope, receive, send)
2025-09-07T16:12:57.644471444Z [err]             ^^^^^^^^^^^^^^^^^^^^^^^^^^^^^^^^^^^^
2025-09-07T16:12:57.644476686Z [err]    File "/opt/venv/lib/python3.12/site-packages/fastapi/applications.py", line 1054, in __call__
2025-09-07T16:12:57.644482023Z [err]      await super().__call__(scope, receive, send)
2025-09-07T16:12:57.644488532Z [err]    File "/opt/venv/lib/python3.12/site-packages/starlette/applications.py", line 113, in __call__
2025-09-07T16:12:57.644495507Z [err]      await self.middleware_stack(scope, receive, send)
2025-09-07T16:12:57.644501224Z [err]    File "/opt/venv/lib/python3.12/site-packages/starlette/middleware/errors.py", line 186, in __call__
2025-09-07T16:12:57.644506473Z [err]      raise exc
2025-09-07T16:12:57.644511787Z [err]    File "/opt/venv/lib/python3.12/site-packages/starlette/middleware/errors.py", line 164, in __call__
2025-09-07T16:12:57.644517714Z [err]      await self.app(scope, receive, _send)
2025-09-07T16:12:57.644523362Z [err]    File "/opt/venv/lib/python3.12/site-packages/starlette/middleware/cors.py", line 93, in __call__
2025-09-07T16:12:57.644528904Z [err]      await self.simple_response(scope, receive, send, request_headers=headers)
2025-09-07T16:12:57.644535826Z [err]    File "/opt/venv/lib/python3.12/site-packages/starlette/middleware/cors.py", line 144, in simple_response
2025-09-07T16:12:57.644541194Z [err]      await self.app(scope, receive, send)
2025-09-07T16:12:57.644547126Z [err]    File "/opt/venv/lib/python3.12/site-packages/starlette/middleware/exceptions.py", line 63, in __call__
2025-09-07T16:12:57.644553309Z [err]      await wrap_app_handling_exceptions(self.app, conn)(scope, receive, send)
2025-09-07T16:12:57.644558461Z [err]    File "/opt/venv/lib/python3.12/site-packages/starlette/_exception_handler.py", line 53, in wrapped_app
2025-09-07T16:12:57.644563501Z [err]      raise exc
2025-09-07T16:12:57.644568676Z [err]    File "/opt/venv/lib/python3.12/site-packages/starlette/_exception_handler.py", line 42, in wrapped_app
2025-09-07T16:12:57.644576158Z [err]      await app(scope, receive, sender)
2025-09-07T16:12:57.644587603Z [err]    File "/opt/venv/lib/python3.12/site-packages/starlette/routing.py", line 716, in __call__
2025-09-07T16:12:57.644591984Z [err]      await self.middleware_stack(scope, receive, send)
2025-09-07T16:12:57.644595984Z [err]    File "/opt/venv/lib/python3.12/site-packages/starlette/routing.py", line 736, in app
2025-09-07T16:12:57.644599842Z [err]      await route.handle(scope, receive, send)
2025-09-07T16:12:57.644603414Z [err]    File "/opt/venv/lib/python3.12/site-packages/starlette/routing.py", line 290, in handle
2025-09-07T16:12:57.644607685Z [err]      await self.app(scope, receive, send)
2025-09-07T16:12:57.644616147Z [err]    File "/opt/venv/lib/python3.12/site-packages/starlette/routing.py", line 78, in app
2025-09-07T16:12:57.644620180Z [err]      await wrap_app_handling_exceptions(app, request)(scope, receive, send)
2025-09-07T16:12:57.644626082Z [err]    File "/opt/venv/lib/python3.12/site-packages/starlette/_exception_handler.py", line 53, in wrapped_app
2025-09-07T16:12:57.644630043Z [err]      raise exc
2025-09-07T16:12:57.644634609Z [err]    File "/opt/venv/lib/python3.12/site-packages/starlette/_exception_handler.py", line 42, in wrapped_app
2025-09-07T16:12:57.644639003Z [err]      await app(scope, receive, sender)
2025-09-07T16:12:57.644645388Z [err]    File "/opt/venv/lib/python3.12/site-packages/starlette/routing.py", line 75, in app
2025-09-07T16:12:57.644652741Z [err]      response = await f(request)
2025-09-07T16:12:57.644657333Z [err]                 ^^^^^^^^^^^^^^^^
2025-09-07T16:12:57.644662854Z [err]    File "/opt/venv/lib/python3.12/site-packages/fastapi/routing.py", line 328, in app
2025-09-07T16:12:57.644668949Z [err]      content = await serialize_response(
2025-09-07T16:12:57.644674872Z [err]                ^^^^^^^^^^^^^^^^^^^^^^^^^
2025-09-07T16:12:57.644680167Z [err]    File "/opt/venv/lib/python3.12/site-packages/fastapi/routing.py", line 202, in serialize_response
2025-09-07T16:12:57.644685663Z [err]      return jsonable_encoder(response_content)
2025-09-07T16:12:57.644695485Z [err]             ^^^^^^^^^^^^^^^^^^^^^^^^^^^^^^^^^^
2025-09-07T16:12:57.644701078Z [err]    File "/opt/venv/lib/python3.12/site-packages/fastapi/encoders.py", line 289, in jsonable_encoder
2025-09-07T16:12:57.644706446Z [err]      encoded_value = jsonable_encoder(
2025-09-07T16:12:57.644711757Z [err]                      ^^^^^^^^^^^^^^^^^
2025-09-07T16:12:57.644717147Z [err]    File "/opt/venv/lib/python3.12/site-packages/fastapi/encoders.py", line 303, in jsonable_encoder
2025-09-07T16:12:57.644722464Z [err]      jsonable_encoder(
2025-09-07T16:12:57.644730139Z [err]    File "/opt/venv/lib/python3.12/site-packages/fastapi/encoders.py", line 297, in jsonable_encoder
2025-09-07T16:12:57.644736040Z [err]      encoded_dict[encoded_key] = encoded_value
2025-09-07T16:12:57.644741830Z [err]      ~~~~~~~~~~~~^^^^^^^^^^^^^
2025-09-07T16:12:57.644748508Z [err]  TypeError: unhashable type: 'list'